
<mujoco>
    <compiler angle="radian" />
  <asset>
    <mesh name="ReU_mesh" file="anchor_scenes/snake_mesh/ReU_Mesh.STL" scale="0.0254 0.0254 0.0254"/>
    <material name="red" rgba="1 0 0 1"/>
    <material name="blue" rgba="0 0 1 1"/>
    <material name="green_dark" rgba="0 0.6 0 1"/>  
    <material name="green_light" rgba="0 0.4 0 1"/>
    <material name="debug_col" rgba="1 0.5 0.5 0.3"/> 
  </asset>
  
  <worldbody>
  <light pos="0 0 1.5" dir="0 0 -1" directional="true"/>

        <body name="mod_0_in" pos="0.0254 0 0.04">
        <joint name="mod_0_freejoint" type="free" damping="5.0"/>

        <geom name = "mod_0_in" type="cylinder" size="0.017018000000000002 0.0127" pos ="0.0254 0.018796 0.01651" euler="1.57079632679 0 0" material="red" 
                contype="1" conaffinity="4" group="1"/>


        <body name="mod_0_body" pos="0 0 0">
        <geom name = "mesh0" type="mesh" mesh="ReU_mesh" pos = "0 0 0" material="green_dark" contype="2" conaffinity="1" group="0"/>

        <geom name = "mod_0_link" type="cylinder" pos ="0.0254 0.0258 0.035559999999999994 " size="0.0258 0.006" material="debug_col" contype="1" conaffinity="4" group="1"/> 

        <body name="mod_0_out" pos="0 0 0" euler="0 0 0 ">
                <inertial pos="0 0 0" mass="0.1" diaginertia="0.001 0.001 0.001"/>
                <geom name = "mod_0_out" type="cylinder" size="0.0125 0.008" pos="0.011921999999999999 0.025654 0.06858" euler="0 1.57079632679 0 " material="debug_col" 
                contype="1" conaffinity="4" group="1"/>


  
        <body name="mod_1_in" pos="0.053085999999999994 0.000254 0.051053999999999995" euler="0 0 1.57079632679">
       
        
        <geom name = "mod_1_in" type="cylinder" size="0.017018000000000002 0.0127" pos ="0.0254 0.018796 0.01651" euler="1.57079632679 0 0" material="debug_col" 
                contype="1" conaffinity="4" group="1"/>
        <joint name="joint_1" type="hinge" pos="0.0254 0.018796 0.01651" axis="0 1 0" range="-1.57079632679 1.57079632679" 
                limited="true" damping="15.0" frictionloss="0.2"/>


        <body name="mod_1_body" pos="0 0 0">
        <geom name = "mesh1" type="mesh" mesh="ReU_mesh" pos = "0 0 0" material="green_dark" contype="2" conaffinity="1" group="0"/>

        <geom name = "mod_1_link" type="cylinder" pos ="0.0254 0.0258 0.035559999999999994 " size="0.0258 0.006" material="debug_col" contype="1" conaffinity="4" group="1"/> 

        <body name="mod_1_out" pos="0 0 0" euler="0 0 0 ">
                <inertial pos="0 0 0" mass="0.1" diaginertia="0.001 0.001 0.001"/>
                <geom name = "mod_1_out" type="cylinder" size="0.0125 0.008" pos="0.011921999999999999 0.025654 0.06858" euler="0 1.57079632679 0 " material="debug_col" 
                contype="1" conaffinity="4" group="1"/>
                    
    
        
  
        <body name="mod_2_in" pos="0.053085999999999994 0.000254 0.051053999999999995" euler="0 0 1.57079632679">
       
        
        <geom name = "mod_2_in" type="cylinder" size="0.017018000000000002 0.0127" pos ="0.0254 0.018796 0.01651" euler="1.57079632679 0 0" material="debug_col" 
                contype="1" conaffinity="4" group="1"/>
        <joint name="joint_2" type="hinge" pos="0.0254 0.018796 0.01651" axis="0 1 0" range="-1.57079632679 1.57079632679" 
                limited="true" damping="15.0" frictionloss="0.2"/>


        <body name="mod_2_body" pos="0 0 0">
        <geom name = "mesh2" type="mesh" mesh="ReU_mesh" pos = "0 0 0" material="green_dark" contype="2" conaffinity="1" group="0"/>

        <geom name = "mod_2_link" type="cylinder" pos ="0.0254 0.0258 0.035559999999999994 " size="0.0258 0.006" material="debug_col" contype="1" conaffinity="4" group="1"/> 

        <body name="mod_2_out" pos="0 0 0" euler="0 0 0 ">
                <inertial pos="0 0 0" mass="0.1" diaginertia="0.001 0.001 0.001"/>
                <geom name = "mod_2_out" type="cylinder" size="0.0125 0.008" pos="0.011921999999999999 0.025654 0.06858" euler="0 1.57079632679 0 " material="debug_col" 
                contype="1" conaffinity="4" group="1"/>
                    
    
        
  
        <body name="mod_3_in" pos="0.053085999999999994 0.000254 0.051053999999999995" euler="0 0 1.57079632679">
       
        
        <geom name = "mod_3_in" type="cylinder" size="0.017018000000000002 0.0127" pos ="0.0254 0.018796 0.01651" euler="1.57079632679 0 0" material="debug_col" 
                contype="1" conaffinity="4" group="1"/>
        <joint name="joint_3" type="hinge" pos="0.0254 0.018796 0.01651" axis="0 1 0" range="-1.57079632679 1.57079632679" 
                limited="true" damping="15.0" frictionloss="0.2"/>


        <body name="mod_3_body" pos="0 0 0">
        <geom name = "mesh3" type="mesh" mesh="ReU_mesh" pos = "0 0 0" material="green_dark" contype="2" conaffinity="1" group="0"/>

        <geom name = "mod_3_link" type="cylinder" pos ="0.0254 0.0258 0.035559999999999994 " size="0.0258 0.006" material="debug_col" contype="1" conaffinity="4" group="1"/> 

        <body name="mod_3_out" pos="0 0 0" euler="0 0 0 ">
                <inertial pos="0 0 0" mass="0.1" diaginertia="0.001 0.001 0.001"/>
                <geom name = "mod_3_out" type="cylinder" size="0.0125 0.008" pos="0.011921999999999999 0.025654 0.06858" euler="0 1.57079632679 0 " material="debug_col" 
                contype="1" conaffinity="4" group="1"/>
                    
    
        
  
        <body name="mod_4_in" pos="0.053085999999999994 0.000254 0.051053999999999995" euler="0 0 1.57079632679">
       
        
        <geom name = "mod_4_in" type="cylinder" size="0.017018000000000002 0.0127" pos ="0.0254 0.018796 0.01651" euler="1.57079632679 0 0" material="debug_col" 
                contype="1" conaffinity="4" group="1"/>
        <joint name="joint_4" type="hinge" pos="0.0254 0.018796 0.01651" axis="0 1 0" range="-1.57079632679 1.57079632679" 
                limited="true" damping="15.0" frictionloss="0.2"/>


        <body name="mod_4_body" pos="0 0 0">
        <geom name = "mesh4" type="mesh" mesh="ReU_mesh" pos = "0 0 0" material="green_dark" contype="2" conaffinity="1" group="0"/>

        <geom name = "mod_4_link" type="cylinder" pos ="0.0254 0.0258 0.035559999999999994 " size="0.0258 0.006" material="debug_col" contype="1" conaffinity="4" group="1"/> 

        <body name="mod_4_out" pos="0 0 0" euler="0 0 0 ">
                <inertial pos="0 0 0" mass="0.1" diaginertia="0.001 0.001 0.001"/>
                <geom name = "mod_4_out" type="cylinder" size="0.0125 0.008" pos="0.011921999999999999 0.025654 0.06858" euler="0 1.57079632679 0 " material="debug_col" 
                contype="1" conaffinity="4" group="1"/>

        <body name="mod_5_in" pos="0.053085999999999994 0.000254 0.051053999999999995" euler="0 0 1.57079632679">

        <geom name = "mod_5_in" type="cylinder" size="0.017018000000000002 0.0127" pos ="0.0254 0.018796 0.01651" euler="1.57079632679 0 0" material="debug_col"
                contype="1" conaffinity="4" group="1"/>
        <joint name="joint_5" type="hinge" pos="0.0254 0.018796 0.01651" axis="0 1 0" range="-1.57079632679 1.57079632679"
                limited="true" damping="15.0" frictionloss="0.2"/>

        <body name="mod_5_body" pos="0 0 0">
        <geom name = "mesh5" type="mesh" mesh="ReU_mesh" pos = "0 0 0" material="green_dark" contype="2" conaffinity="1" group="0"/>

        <geom name = "mod_5_link" type="cylinder" pos ="0.0254 0.0258 0.035559999999999994 " size="0.0258 0.006" material="debug_col" contype="1" conaffinity="4" group="1"/>

        <body name="mod_5_out" pos="0 0 0" euler="0 0 0 ">
                <inertial pos="0 0 0" mass="0.1" diaginertia="0.001 0.001 0.001"/>
                <geom name = "mod_5_out" type="cylinder" size="0.0125 0.008" pos="0.011921999999999999 0.025654 0.06858" euler="0 1.57079632679 0 " material="debug_col"
                contype="1" conaffinity="4" group="1"/>

    </body> </body> </body>

    </body> </body> </body>

    </body> </body> </body>

    </body> </body> </body>

    </body> </body> </body>

    </body> </body> </body>
    


</worldbody>

<actuator>


      <position name="servo_1_pos" joint="joint_1" kp="10" ctrlrange="-1.5708 1.5708" ctrllimited="true" forcerange="-10.0 10.0" forcelimited="true"/>
      
      <position name="servo_2_pos" joint="joint_2" kp="10" ctrlrange="-1.5708 1.5708" ctrllimited="true" forcerange="-10.0 10.0" forcelimited="true"/>
      
      <position name="servo_3_pos" joint="joint_3" kp="10" ctrlrange="-1.5708 1.5708" ctrllimited="true" forcerange="-10.0 10.0" forcelimited="true"/>
      
      <position name="servo_4_pos" joint="joint_4" kp="10" ctrlrange="-1.5708 1.5708" ctrllimited="true" forcerange="-10.0 10.0" forcelimited="true"/>

      <position name="servo_5_pos" joint="joint_5" kp="10" ctrlrange="-1.5708 1.5708" ctrllimited="true" forcerange="-10.0 10.0" forcelimited="true"/>
      

</actuator>
</mujoco>

